Workbook

Sheet Dados_Brutos
A1: 🚗 Dados Brutos — Base Porsche (como recebida)
A2: << Voltar ao Dashboard
A4: ID Venda | B4: Data (bruta) | C4: Cliente (bruto) | D4: Modelo | E4: Ano (bruto) | F4: Preço (bruto) | G4: Quilometragem (bruta) | H4: Pagamento (bruto) | I4: Cidade (bruta) | J4: Estado (bruto) | K4: Vendedor (bruto) | L4: Status (bruto)
A5: 6 | B5: 2024-02-30 | C5: Michael Adams | D5: 718 Cayman | E5: 2022 | F5: $79,500.00 | G5: 9,800 miles | H5: Credit card | I5: boston | J5: ma | K5: kevin | L5: delivered
A6: 7 | B6: 03/14/2024 | C6: SOPHIA Miller | D6: 911 Turbo S | E6: twenty twenty four | F6: 235000 USD | G6: 1.200 mi | H6: wire transfer | I6: Seattle | J6: Washington | K6: AMANDA scott | L6: DELIVERED
A7: 8 | B7: 2024-04-18 00:00:00 | C7: Daniel-Jones | D7: Cayenne Coupe | E7: 2023 | F7: USD 112.750 | G7: Miles: 6,400 | H7: Financing plan | I7: austin | J7: tx | K7: Brian Hall | L7: in Transit
A8: 9 | B8: April 31st, 2024 | C8: Olivia Brown | D8: Macan S | E8: 2021 | F8: 68.900 dollars | G8: 28 | H8: CASH | I8: Denver | J8: colorado | K8: jessica | L8: Pending
A9: 10 | B9: 2024-05-22 00:00:00 | C9: Ethan Wilson | D9: Taycan 4S | E9: 2024 | F9: $121k | G9: zero miles | H9: bank-transfer | I9: los angeles | J9: ca | K9: Thomas King | L9: delivered!!!
A10: 11 | B10: 2024-08-06 00:00:00 | C10: Ava Martinez | D10: Panamera 4 | E10: 20-23 | F10: 104,500 USD | G10: 14.500 miles | H10: Credit Card | I10: Miami | J10: FL | K10: LISA ray | L10: cancelled
A11: 12 | B11: 2024.07.11 | C11: Noah Davis | D11: 911 Carrera S | E11: 2020 | F11: USD $96,300 | G11: 41,000mi | H11: lease | I11: new york | J11: New York | K11: Mark Evans | L11: DELIVERD
A12: 13 | B12: 2024/15/07 | C12: Isabella Garcia | D12: Cayenne E-Hybrid | E12: 2022 | F12: $89.750,00 | G12: KM 18,900 | H12: bank wire | I12: San Diego | J12: CA | K12: nancy reed | L12: pending approval
A13: 14 | B13: 08/19/24 | C13: Liam Rodriguez | D13: 718 Boxster | E13: two thousand twenty one | F13: 73500 | G13: 22,300 miles | H13: debit card | I13: chicago | J13: IL | K13: George Bell | L13: shipped
A14: 15 | B14: 2024-09-02 00:00:00 | C14: Mia Hernandez | D14: Macan GTS | E14: 2024 | F14: 95,000 dollars | G14: 3.500 mi | H14: Financing | I14: phoenix | J14: arizona | K14: Helen Brooks | L14: IN TRANSIT
A15: 16 | B15: September 17, 2024 | C15: James Lopez | D15: Taycan Turbo | E15: 2023 | F15: $153,200.50 | G15: 11 | H15: ACH payment | I15: dallas | J15: tx | K15: samuel price | L15: delivered
... A104: 105 | B104: 2027.10.01 | C104: Madison Powell | D104: 911 Dakar | E104: twenty twenty four | F104: $271,700 | G104: 1,050 miles | H104: Leasing | I104: new orleans | J104: la | K104: Steve Ross | L104: Delivered
A106: Esta aba reproduz a base exatamente como recebida (texto livre, formatos inconsistentes de data/preço/quilometragem, capitalização irregular etc.). É a ENTRADA do Agente de Tratamento de Dados — veja a aba Dados_Tratados.

Sheet Dados_Tratados
A1: ✅ Dados Tratados — Saída do Agente de Tratamento de Dados
A2: << Voltar ao Dashboard
A3: Gerada automaticamente pelo script agente_tratamento_dados.py — não editar manualmente.
A4: ID Venda | B4: Data da Venda | C4: Cliente | D4: Modelo | E4: Ano | F4: Preço (R$) | G4: Quilometragem (mi) | H4: Pagamento | I4: Cidade | J4: UF | K4: Vendedor | L4: Status Entrega | M4: Ano-Mês
A5: 6 | B5: Data inválida | C5: Michael Adams | D5: 718 Cayman | E5: 2022 | F5: 79500 | G5: 9800 | H5: Credit Card | I5: Boston | J5: MA | K5: Kevin Brown | L5: Delivered
A6: 7 | B6: 2024-03-14 | C6: Sophia Miller | D6: 911 Turbo S | E6: 2024 | F6: 235000 | G6: 1200 | H6: Wire Transfer | I6: Seattle | J6: WA | K6: Amanda Scott | L6: Delivered | M6: 2024-03
A7: 8 | B7: 2024-04-18 | C7: Daniel Jones | D7: Cayenne Coupe | E7: 2023 | F7: 112750 | G7: 6400 | H7: Financing | I7: Austin | J7: TX | K7: Brian Hall | L7: In Transit | M7: 2024-04
A8: 9 | B8: Data inválida | C8: Olivia Brown | D8: Macan S | E8: 2021 | F8: 68900 | G8: 28 | H8: Cash | I8: Denver | J8: CO | K8: Jessica White | L8: Pending
A9: 10 | B9: 2024-05-22 | C9: Ethan Wilson | D9: Taycan 4S | E9: 2024 | F9: 121000 | G9: 0 | H9: Bank Transfer | I9: Los Angeles | J9: CA | K9: Thomas King | L9: Delivered | M9: 2024-05
A10: 11 | B10: 2024-08-06 | C10: Ava Martinez | D10: Panamera 4 | E10: 2023 | F10: 104500 | G10: 14500 | H10: Credit Card | I10: Miami | J10: FL | K10: Lisa Ray | L10: Cancelled | M10: 2024-08
A11: 12 | B11: 2024-07-11 | C11: Noah Davis | D11: 911 Carrera S | E11: 2020 | F11: 96300 | G11: 41000 | H11: Lease | I11: New York | J11: NY | K11: Mark Evans | L11: Delivered | M11: 2024-07
A12: 13 | B12: Data inválida | C12: Isabella Garcia | D12: Cayenne E-Hybrid | E12: 2022 | F12: 89750 | G12: 11744 | H12: Wire Transfer | I12: San Diego | J12: CA | K12: Nancy Reed | L12: Pending Approval
A13: 14 | B13: 2024-08-19 | C13: Liam Rodriguez | D13: 718 Boxster | E13: 2021 | F13: 73500 | G13: 22300 | H13: Debit Card | I13: Chicago | J13: IL | K13: George Bell | L13: Shipped | M13: 2024-08
A14: 15 | B14: 2024-09-02 | C14: Mia Hernandez | D14: Macan GTS | E14: 2024 | F14: 95000 | G14: 3500 | H14: Financing | I14: Phoenix | J14: AZ | K14: Helen Brooks | L14: In Transit | M14: 2024-09
A15: 16 | B15: 2024-09-17 | C15: James Lopez | D15: Taycan Turbo | E15: 2023 | F15: 153200.5 | G15: 11 | H15: ACH Payment | I15: Dallas | J15: TX | K15: Samuel Price | L15: Delivered | M15: 2024-09
A16: 17 | B16: Data inválida | C16: Charlotte Young | D16: 911 GT3 | E16: 2024 | F16: 241000 | G16: 750 | H16: Wire Transfer | I16: Las Vegas | J16: NV | K16: Peter Ford | L16: Pending
A17: 18 | B17: 2024-05-11 | C17: Benjamin Allen | D17: Panamera Turbo S | E17: 2022 | F17: 132000 | G17: 19250 | H17: Cash | I17: San Jose | J17: CA | K17: Angela Green | L17: Delivered | M17: 2024-05
A18: 19 | B18: 2024-12-12 | C18: Amelia King | D18: Cayenne Turbo GT | E18: 2024 | F18: 188000 | G18: 2100 | H18: Crypto Payment | I18: Houston | J18: TX | K18: Victor Stone | L18: Awaiting Delivery | M18: 2024-12
A19: 20 | B19: 2024-12-25 | C19: Lucas Wright | D19: 911 Carrera Cabriolet | E19: 2023 | F19: 127800 | G19: 12000 | H19: Credit Card | I19: Atlanta | J19: GA | K19: Rachel Turner | L19: Delivered | M19: 2024-12
A20: 21 | B20: 2025-01-06 | C20: Harper Scott | D20: Macan | E20: 2021 | F20: 58900 | G20: 33700 | H20: Bank Transfer | I20: Orlando | J20: FL | K20: Chris Moore | L20: Pending | M20: 2025-01
A21: 22 | B21: Data inválida | C21: Henry Torres | D21: 718 Spyder RS | E21: 2024 | F21: 164000 | G21: 900 | H21: Financing | I21: Portland | J21: OR | K21: Laura Hill | L21: In Transit
A22: 23 | B22: 2025-02-14 | C22: Evelyn Nguyen | D22: Taycan Cross Turismo | E22: 2023 | F22: 118500 | G22: 7800 | H22: Wire Transfer | I22: Charlotte | J22: NC | K22: Martin Young | L22: Delivered | M22: 2025-02
A23: 24 | B23: Data inválida | C23: Alexander Flores | D23: Cayenne S | E23: 2022 | F23: 91300 | G23: 16000 | H23: Credit Card | I23: Nashville | J23: TN | K23: Diana Cooper | L23: Pending
A24: 25 | B24: 2025-03-21 | C24: Abigail Carter | D24: 911 Targa 4S | E24: 2024 | F24: 158750 | G24: 2500 | H24: Lease | I24: Minneapolis | J24: MN | K24: Steve Gray | L24: Delivered | M24: 2025-03
A25: 26 | B25: 2025-03-28 | C25: Jack Mitchell | D25: Panamera | E25: 2020 | F25: 72000 | G25: 49000 | H25: Bank Transfer | I25: Philadelphia | J25: PA | K25: Olivia Ross | L25: Cancelled | M25: 2025-03
A26: 27 | B26: 2025-04-09 | C26: Emily Perez | D26: Macan Electric | E26: 2025 | F26: 86500 | G26: 0 | H26: Wire Transfer | I26: San Antonio | J26: TX | K26: Patrick Wood | L26: Delivered | M26: 2025-04
A27: 28 | B27: Data inválida | C27: William Roberts | D27: 911 Dakar | E27: 2024 | F27: 270000 | G27: 1050 | H27: Cash | I27: Salt Lake City | J27: UT | K27: Karen Diaz | L27: Awaiting Pickup
A28: 29 | B28: 2025-05-12 | C28: Sofia Turner | D28: Taycan GTS | E28: 2023 | F28: 139000 | G28: 6250 | H28: Financing | I28: Raleigh | J28: NC | K28: Justin Cox | L28: In Transit | M28: 2025-05
A29: 30 | B29: 2025-06-18 | C29: Mason Phillips | D29: Cayenne | E29: 2021 | F29: 76800 | G29: 38400 | H29: Credit Card | I29: Detroit | J29: MI | K29: Betty Ward | L29: Delivered | M29: 2025-06
A30: 31 | B30: Data inválida | C30: Ella Campbell | D30: 718 Cayman GT4 RS | E30: 2024 | F30: 173600 | G30: 400 | H30: Wire Transfer | I30: Columbus | J30: OH | K30: Gary Reed | L30: Pending
A31: 32 | B31: 2025-07-07 | C31: Logan Parker | D31: 911 Carrera GTS | E31: 2022 | F31: 119900 | G31: 13600 | H31: Cash | I31: Indianapolis | J31: IN | K31: Maria Foster | L31: Delivered | M31: 2025-07
A32: 33 | B32: 2025-07-22 | C32: Grace Evans | D32: Panamera 4 E-Hybrid | E32: 2023 | F32: 109250 | G32: 8900 | H32: Lease | I32: Fort Worth | J32: TX | K32: Harold Bennett | L32: In Transit | M32: 2025-07
A33: 34 | B33: 2025-08-14 | C33: Jacob Edwards | D33: Macan T | E33: 2022 | F33: 82000 | G33: 21750 | H33: Wire Transfer | I33: Jacksonville | J33: FL | K33: Teresa Cook | L33: Delivered | M33: 2025-08
A34: 35 | B34: 2025-09-01 | C34: Victoria Collins | D34: Taycan Turbo S | E34: 2025 | F34: 214000 | G34: 0 | H34: Crypto Payment | I34: San Diego | J34: CA | K34: Frank Morgan | L34: Pending Review | M34: 2025-09
A35: 36 | B35: Data inválida | C35: Andrew Simmons | D35: 911 Carrera | E35: 2024 | F35: 124500 | G35: 4800 | H35: Credit Card | I35: Tampa | J35: FL | K35: Natalie | L35: Delivered
A36: 37 | B36: 2025-09-18 | C36: Chloe Bennett | D36: Cayenne S | E36: 2023 | F36: 98200 | G36: 12200 | H36: Bank Transfer | I36: Sacramento | J36: CA | K36: Eric Woods | L36: Pending | M36: 2025-09
A37: 38 | B37: 2025-10-04 | C37: Ryan Cooper | D37: Macan | E37: 2022 | F37: 67500 | G37: 24100 | H37: Financing | I37: Cleveland | J37: OH | K37: Patricia Fox | L37: Delivered | M37: 2025-10
A38: 39 | B38: 2025-10-12 | C38: Hannah Reed | D38: Taycan | E38: 2025 | F38: 116900 | G38: 0 | H38: Wire Transfer | I38: Milwaukee | J38: WI | K38: Alan Price | L38: In Transit | M38: 2025-10
A39: 40 | B39: 2025-10-29 | C39: Dylan Parker | D39: Panamera 4S | E39: 2024 | F39: 112000 | G39: 10 | H39: Cash | I39: Kansas City | J39: MO | K39: Sandra Hill | L39: Delivered | M39: 2025-10
A40: 41 | B40: 2025-02-11 | C40: Lily Coleman | D40: 718 Boxster | E40: 2021 | F40: 74000 | G40: 31000 | H40: Debit Card | I40: Omaha | J40: NE | K40: Victor Lee | L40: Cancelled | M40: 2025-02
...

Sheet Qualidade_Dados
A1: 🔍 Qualidade dos Dados — Relatório do Agente
A2: << Voltar ao Dashboard
A4: Acurácia por Campo (vs. gabarito de referência da base)
A5: Campo | B5: Acurácia | C5: Divergências
A6: Data da venda | B6: 1 | C6: 0
A7: Ano do modelo | B7: 1 | C7: 0
A8: Preço de venda | B8: 1 | C8: 0
A9: Quilometragem | B9: 1 | C9: 0
A10: Forma de pagamento | B10: 1 | C10: 0
A11: Cidade | B11: 1 | C11: 0
A12: Estado (UF) | B12: 1 | C12: 0
A13: Status de entrega | B13: 1 | C13: 0
A15: Nomes de cliente/vendedor (customer_name, salesperson) não têm coluna de gabarito na base original; a limpeza aplicada (Title Case + correção de hífen + reconciliação de vendedores com apenas o primeiro nome) foi validada manualmente — ver seção abaixo.
A19: Datas Marcadas como Inválidas (24 registros)
A20: ID Venda | B20: Data bruta original
A21: 6 | B21: 2024-02-30
A22: 9 | B22: April 31st, 2024
A23: 13 | B23: 2024/15/07
A24: 17 | B24: 2024-10-40
A25: 22 | B25: 01/32/2025
A26: 24 | B26: February 29th, 2025
A27: 28 | B27: 2025/04/31
A28: 31 | B28: 06/31/2025
A29: 36 | B29: 2025-09-31
A30: 43 | B30: 2025/18/11
A31: 44 | B31: November 31st, 2025
A32: 47 | B32: 2025-12-40
... A44: 102 | B44: August 32nd, 2027
A46: Estas datas correspondem a valores impossíveis no calendário (ex.: 30 de fevereiro, mês 15, dia 40) ou a formatos ambíguos demais para interpretar com segurança. O agente optou por sinalizar como inválidas em vez de adivinhar — essas vendas permanecem no dashboard (contam para faturamento e unidades), mas ficam de fora dos gráficos que dependem de data (ex.: faturamento mensal).
A51: Reconciliação de Vendedores (nome incompleto → nome completo)
A52: Nome bruto | B52: Nome reconciliado
A53: jessica | B53: Jessica White
A54: kevin | B54: Kevin Brown
A55: monica | B55: Monica Green
A56: natalie | B56: Natalie (sem correspondência única — mantido como está)
A58: Quando um vendedor aparece em algumas linhas só com o primeiro nome (ex.: 'kevin') e existe exatamente UM nome completo compatível na base (ex.: 'Kevin Brown'), o agente reconcilia os dois registros como a mesma pessoa. Quando há ambiguidade ou nenhuma correspondência (ex.: 'natalie', sem nenhuma 'Natalie Sobrenome' na base), o nome é mantido como veio, para não inventar dados.

Sheet Resumo
A1: 📊 Tabelas de Apoio (calculadas a partir da aba Dados_Tratados)
A2: << Voltar ao Dashboard
A4: Faturamento por Ano | E4: Faturamento por Forma de Pagamento | I4: Pedidos por Status de Entrega | M4: Faturamento por Modelo (base) | Q4: Faturamento por Estado (base) | Y4: Faturamento por Vendedor (base)
A5: Ano | B5: Faturamento (R$) | E5: Forma de Pagamento | F5: Faturamento (R$) | I5: Status | J5: Pedidos | M5: Modelo | N5: Faturamento (R$) | Q5: UF | R5: Faturamento (R$) | Y5: Vendedor | Z5: Faturamento (R$)
A6: 2024 | B6: =SUMPRODUCT((LEFT(Dados_Tratados!$M$5:$M$104,4)=TEXT(A6,"0"))*Dados_Tratados!$F$5:$F$104) -> 1439050.5 | E6: Cash | F6: =SUMIF(Dados_Tratados!$H$5:$H$104,E6,Dados_Tratados!$F$5:$F$104) -> 1326550 | I6: Delivered | J6: =COUNTIF(Dados_Tratados!$L$5:$L$104,I6) -> 41 | M6: 718 Boxster | N6: =SUMIF(Dados_Tratados!$D$5:$D$104,M6,Dados_Tratados!$F$5:$F$104) -> 219400 | Q6: AK | R6: =SUMIF(Dados_Tratados!$J$5:$J$104,Q6,Dados_Tratados!$F$5:$F$104) -> 132000 | Y6: Alan Price | Z6: =SUMIF(Dados_Tratados!$K$5:$K$104,Y6,Dados_Tratados!$F$5:$F$104) -> 116900
A7: 2025 | B7: =SUMPRODUCT((LEFT(Dados_Tratados!$M$5:$M$104,4)=TEXT(A7,"0"))*Dados_Tratados!$F$5:$F$104) -> 2167500 | E7: Credit Card | F7: =SUMIF(Dados_Tratados!$H$5:$H$104,E7,Dados_Tratados!$F$5:$F$104) -> 1987700 | I7: Shipped | J7: =COUNTIF(Dados_Tratados!$L$5:$L$104,I7) -> 4 | M7: 718 Boxster GTS | N7: =SUMIF(Dados_Tratados!$D$5:$D$104,M7,Dados_Tratados!$F$5:$F$104) -> 91500 | Q7: AZ | R7: =SUMIF(Dados_Tratados!$J$5:$J$104,Q7,Dados_Tratados!$F$5:$F$104) -> 695950 | Y7: Amanda Lee | Z7: =SUMIF(Dados_Tratados!$K$5:$K$104,Y7,Dados_Tratados!$F$5:$F$104) -> 84500
A8: 2026 | B8: =SUMPRODUCT((LEFT(Dados_Tratados!$M$5:$M$104,4)=TEXT(A8,"0"))*Dados_Tratados!$F$5:$F$104) -> 3901150 | E8: Debit Card | F8: =SUMIF(Dados_Tratados!$H$5:$H$104,E8,Dados_Tratados!$F$5:$F$104) -> 326350 | I8: In Transit | J8: =COUNTIF(Dados_Tratados!$L$5:$L$104,I8) -> 15 | M8: 718 Cayman | N8: =SUMIF(Dados_Tratados!$D$5:$D$104,M8,Dados_Tratados!$F$5:$F$104) -> 228300 | Q8: CA | R8: =SUMIF(Dados_Tratados!$J$5:$J$104,Q8,Dados_Tratados!$F$5:$F$104) -> 1973350 | Y8: Amanda Scott | Z8: =SUMIF(Dados_Tratados!$K$5:$K$104,Y8,Dados_Tratados!$F$5:$F$104) -> 235000
A9: 2027 | B9: =SUMPRODUCT((LEFT(Dados_Tratados!$M$5:$M$104,4)=TEXT(A9,"0"))*Dados_Tratados!$F$5:$F$104) -> 1979000 | E9: Bank Transfer | F9: =SUMIF(Dados_Tratados!$H$5:$H$104,E9,Dados_Tratados!$F$5:$F$104) -> 900500 | I9: Awaiting Pickup | J9: =COUNTIF(Dados_Tratados!$L$5:$L$104,I9) -> 4 | M9: 718 Cayman GT4 RS | N9: =SUMIF(Dados_Tratados!$D$5:$D$104,M9,Dados_Tratados!$F$5:$F$104) -> 350000 | Q9: CO | R9: =SUMIF(Dados_Tratados!$J$5:$J$104,Q9,Dados_Tratados!$F$5:$F$104) -> 337600 | Y9: Amber Clark | Z9: =SUMIF(Dados_Tratados!$K$5:$K$104,Y9,Dados_Tratados!$F$5:$F$104) -> 255000
E10: Wire Transfer | F10: =SUMIF(Dados_Tratados!$H$5:$H$104,E10,Dados_Tratados!$F$5:$F$104) -> 3979450 | I10: Awaiting Delivery | J10: =COUNTIF(Dados_Tratados!$L$5:$L$104,I10) -> 5 | M10: 718 Cayman S | N10: =SUMIF(Dados_Tratados!$D$5:$D$104,M10,Dados_Tratados!$F$5:$F$104) -> 82750 | Q10: FL | R10: =SUMIF(Dados_Tratados!$J$5:$J$104,Q10,Dados_Tratados!$F$5:$F$104) -> 566600 | Y10: Angela Green | Z10: =SUMIF(Dados_Tratados!$K$5:$K$104,Y10,Dados_Tratados!$F$5:$F$104) -> 263600
E11: ACH Payment | F11: =SUMIF(Dados_Tratados!$H$5:$H$104,E11,Dados_Tratados!$F$5:$F$104) -> 543000.5 | I11: Pending | J11: =COUNTIF(Dados_Tratados!$L$5:$L$104,I11) -> 17 | M11: 718 Spyder RS | N11: =SUMIF(Dados_Tratados!$D$5:$D$104,M11,Dados_Tratados!$F$5:$F$104) -> 333000 | Q11: GA | R11: =SUMIF(Dados_Tratados!$J$5:$J$104,Q11,Dados_Tratados!$F$5:$F$104) -> 434800 | Y11: Angela Moore | Z11: =SUMIF(Dados_Tratados!$K$5:$K$104,Y11,Dados_Tratados!$F$5:$F$104) -> 176400
E12: Financing | F12: =SUMIF(Dados_Tratados!$H$5:$H$104,E12,Dados_Tratados!$F$5:$F$104) -> 1426650 | I12: Pending Approval | J12: =COUNTIF(Dados_Tratados!$L$5:$L$104,I12) -> 4 | M12: 911 Carrera | N12: =SUMIF(Dados_Tratados!$D$5:$D$104,M12,Dados_Tratados!$F$5:$F$104) -> 251400 | Q12: HI | R12: =SUMIF(Dados_Tratados!$J$5:$J$104,Q12,Dados_Tratados!$F$5:$F$104) -> 104600 | Y12: Betty James | Z12: =SUMIF(Dados_Tratados!$K$5:$K$104,Y12,Dados_Tratados!$F$5:$F$104) -> 268900
E13: Lease | F13: =SUMIF(Dados_Tratados!$H$5:$H$104,E13,Dados_Tratados!$F$5:$F$104) -> 1254600 | I13: Pending Review | J13: =COUNTIF(Dados_Tratados!$L$5:$L$104,I13) -> 2 | M13: 911 Carrera Cabriolet | N13: =SUMIF(Dados_Tratados!$D$5:$D$104,M13,Dados_Tratados!$F$5:$F$104) -> 259800 | Q13: ID | R13: =SUMIF(Dados_Tratados!$J$5:$J$104,Q13,Dados_Tratados!$F$5:$F$104) -> 224000 | Y13: Betty Ward | Z13: =SUMIF(Dados_Tratados!$K$5:$K$104,Y13,Dados_Tratados!$F$5:$F$104) -> 76800
E14: Crypto Payment | F14: =SUMIF(Dados_Tratados!$H$5:$H$104,E14,Dados_Tratados!$F$5:$F$104) -> 1083000 | I14: Awaiting Review | J14: =COUNTIF(Dados_Tratados!$L$5:$L$104,I14) -> 1 | M14: 911 Carrera GTS | N14: =SUMIF(Dados_Tratados!$D$5:$D$104,M14,Dados_Tratados!$F$5:$F$104) -> 241650 | Q14: IL | R14: =SUMIF(Dados_Tratados!$J$5:$J$104,Q14,Dados_Tratados!$F$5:$F$104) -> 166100 | Y14: Brian Allen | Z14: =SUMIF(Dados_Tratados!$K$5:$K$104,Y14,Dados_Tratados!$F$5:$F$104) -> 99950
I15: Cancelled | J15: =COUNTIF(Dados_Tratados!$L$5:$L$104,I15) -> 7 | M15: 911 Carrera S | N15: =SUMIF(Dados_Tratados!$D$5:$D$104,M15,Dados_Tratados!$F$5:$F$104) -> 200900 | Q15: IN | R15: =SUMIF(Dados_Tratados!$J$5:$J$104,Q15,Dados_Tratados!$F$5:$F$104) -> 119900 | Y15: Brian Hall | Z15: =SUMIF(Dados_Tratados!$K$5:$K$104,Y15,Dados_Tratados!$F$5:$F$104) -> 182550
M16: 911 Dakar | N16: =SUMIF(Dados_Tratados!$D$5:$D$104,M16,Dados_Tratados!$F$5:$F$104) -> 810600 | Q16: KS | R16: =SUMIF(Dados_Tratados!$J$5:$J$104,Q16,Dados_Tratados!$F$5:$F$104) -> 351600 | Y16: Carl Simmons | Z16: =SUMIF(Dados_Tratados!$K$5:$K$104,Y16,Dados_Tratados!$F$5:$F$104) -> 141800
M17: 911 GT3 | N17: =SUMIF(Dados_Tratados!$D$5:$D$104,M17,Dados_Tratados!$F$5:$F$104) -> 697500 | Q17: KY | R17: =SUMIF(Dados_Tratados!$J$5:$J$104,Q17,Dados_Tratados!$F$5:$F$104) -> 169000 | Y17: Chris Moore | Z17: =SUMIF(Dados_Tratados!$K$5:$K$104,Y17,Dados_Tratados!$F$5:$F$104) -> 141650
M18: 911 GT3 RS | N18: =SUMIF(Dados_Tratados!$D$5:$D$104,M18,Dados_Tratados!$F$5:$F$104) -> 286500 | Q18: LA | R18: =SUMIF(Dados_Tratados!$J$5:$J$104,Q18,Dados_Tratados!$F$5:$F$104) -> 361400 | Y18: Diana Cooper | Z18: =SUMIF(Dados_Tratados!$K$5:$K$104,Y18,Dados_Tratados!$F$5:$F$104) -> 202300
M19: 911 Targa 4 | N19: =SUMIF(Dados_Tratados!$D$5:$D$104,M19,Dados_Tratados!$F$5:$F$104) -> 284500 | Q19: MA | R19: =SUMIF(Dados_Tratados!$J$5:$J$104,Q19,Dados_Tratados!$F$5:$F$104) -> 328800 | Y19: Diana Long | Z19: =SUMIF(Dados_Tratados!$K$5:$K$104,Y19,Dados_Tratados!$F$5:$F$104) -> 351600
M20: 911 Targa 4S | N20: =SUMIF(Dados_Tratados!$D$5:$D$104,M20,Dados_Tratados!$F$5:$F$104) -> 315250 | Q20: MI | R20: =SUMIF(Dados_Tratados!$J$5:$J$104,Q20,Dados_Tratados!$F$5:$F$104) -> 76800 | Y20: Eric Woods | Z20: =SUMIF(Dados_Tratados!$K$5:$K$104,Y20,Dados_Tratados!$F$5:$F$104) -> 98200
M21: 911 Turbo | N21: =SUMIF(Dados_Tratados!$D$5:$D$104,M21,Dados_Tratados!$F$5:$F$104) -> 198300 | Q21: MN | R21: =SUMIF(Dados_Tratados!$J$5:$J$104,Q21,Dados_Tratados!$F$5:$F$104) -> 158750 | Y21: Frank Morgan | Z21: =SUMIF(Dados_Tratados!$K$5:$K$104,Y21,Dados_Tratados!$F$5:$F$104) -> 214000
M22: 911 Turbo S | N22: =SUMIF(Dados_Tratados!$D$5:$D$104,M22,Dados_Tratados!$F$5:$F$104) -> 726300 | Q22: MO | R22: =SUMIF(Dados_Tratados!$J$5:$J$104,Q22,Dados_Tratados!$F$5:$F$104) -> 178750 | Y22: Frank Reed | Z22: =SUMIF(Dados_Tratados!$K$5:$K$104,Y22,Dados_Tratados!$F$5:$F$104) -> 132000
M23: Cayenne | N23: =SUMIF(Dados_Tratados!$D$5:$D$104,M23,Dados_Tratados!$F$5:$F$104) -> 239700 | Q23: NC | R23: =SUMIF(Dados_Tratados!$J$5:$J$104,Q23,Dados_Tratados!$F$5:$F$104) -> 510100 | Y23: Gary Price | Z23: =SUMIF(Dados_Tratados!$K$5:$K$104,Y23,Dados_Tratados!$F$5:$F$104) -> 101300
M24: Cayenne Coupe | N24: =SUMIF(Dados_Tratados!$D$5:$D$104,M24,Dados_Tratados!$F$5:$F$104) -> 436250 | Q24: NE | R24: =SUMIF(Dados_Tratados!$J$5:$J$104,Q24,Dados_Tratados!$F$5:$F$104) -> 292000 | Y24: Gary Reed | Z24: =SUMIF(Dados_Tratados!$K$5:$K$104,Y24,Dados_Tratados!$F$5:$F$104) -> 173600
M25: Cayenne E-Hybrid | N25: =SUMIF(Dados_Tratados!$D$5:$D$104,M25,Dados_Tratados!$F$5:$F$104) -> 373650 | Q25: NJ | R25: =SUMIF(Dados_Tratados!$J$5:$J$104,Q25,Dados_Tratados!$F$5:$F$104) -> 208450 | Y25: George Bell | Z25: =SUMIF(Dados_Tratados!$K$5:$K$104,Y25,Dados_Tratados!$F$5:$F$104) -> 73500
M26: Cayenne S | N26: =SUMIF(Dados_Tratados!$D$5:$D$104,M26,Dados_Tratados!$F$5:$F$104) -> 289450 | Q26: NM | R26: =SUMIF(Dados_Tratados!$J$5:$J$104,Q26,Dados_Tratados!$F$5:$F$104) -> 198300 | Y26: George Hall | Z26: =SUMIF(Dados_Tratados!$K$5:$K$104,Y26,Dados_Tratados!$F$5:$F$104) -> 121750
M27: Cayenne Turbo | N27: =SUMIF(Dados_Tratados!$D$5:$D$104,M27,Dados_Tratados!$F$5:$F$104) -> 146800 | Q27: NV | R27: =SUMIF(Dados_Tratados!$J$5:$J$104,Q27,Dados_Tratados!$F$5:$F$104) -> 643400 | Y27: Grace Morris | Z27: =SUMIF(Dados_Tratados!$K$5:$K$104,Y27,Dados_Tratados!$F$5:$F$104) -> 189600
... M38: Panamera Turbo | N38: =SUMIF(Dados_Tratados!$D$5:$D$104,M38,Dados_Tratados!$F$5:$F$104) -> 273500 | Q38: WI | R38: =SUMIF(Dados_Tratados!$J$5:$J$104,Q38,Dados_Tratados!$F$5:$F$104) -> 211200 | Y38: Karen Stone | Z38: =SUMIF(Dados_Tratados!$K$5:$K$104,Y38,Dados_Tratados!$F$5:$F$104) -> 78400
M39: Panamera Turbo S | N39: =SUMIF(Dados_Tratados!$D$5:$D$104,M39,Dados_Tratados!$F$5:$F$104) -> 266000 | Y39: Kevin Brown | Z39: =SUMIF(Dados_Tratados!$K$5:$K$104,Y39,Dados_Tratados!$F$5:$F$104) -> 206400
M40: Taycan | N40: =SUMIF(Dados_Tratados!$D$5:$D$104,M40,Dados_Tratados!$F$5:$F$104) -> 236800 | Y40: Kyle Perry | Z40: =SUMIF(Dados_Tratados!$K$5:$K$104,Y40,Dados_Tratados!$F$5:$F$104) -> 146800
M41: Taycan 4S | N41: =SUMIF(Dados_Tratados!$D$5:$D$104,M41,Dados_Tratados!$F$5:$F$104) -> 514300 | Q41: Top 10 Estados por Faturamento | Y41: Laura Hill | Z41: =SUMIF(Dados_Tratados!$K$5:$K$104,Y41,Dados_Tratados!$F$5:$F$104) -> 255300
M42: Taycan Cross Turismo | N42: =SUMIF(Dados_Tratados!$D$5:$D$104,M42,Dados_Tratados!$F$5:$F$104) -> 246400 | Q42: UF | R42: Faturamento (R$) | Y42: Laura West | Z42: =SUMIF(Dados_Tratados!$K$5:$K$104,Y42,Dados_Tratados!$F$5:$F$104) -> 186200
M43: Taycan GTS | N43: =SUMIF(Dados_Tratados!$D$5:$D$104,M43,Dados_Tratados!$F$5:$F$104) -> 429500 | Q43: =INDEX($Q$6:$Q$38,MATCH(R43,$R$6:$R$38,0)) -> TX | R43: =LARGE($R$6:$R$38,1) -> 2023400.5 | Y43: Linda Cole | Z43: =SUMIF(Dados_Tratados!$K$5:$K$104,Y43,Dados_Tratados!$F$5:$F$104) -> 284500
M44: Taycan Turbo | N44: =SUMIF(Dados_Tratados!$D$5:$D$104,M44,Dados_Tratados!$F$5:$F$104) -> 475700.5 | Q44: =INDEX($Q$6:$Q$38,MATCH(R44,$R$6:$R$38,0)) -> CA | R44: =LARGE($R$6:$R$38,2) -> 1973350 | Y44: Lisa Dunn | Z44: =SUMIF(Dados_Tratados!$K$5:$K$104,Y44,Dados_Tratados!$F$5:$F$104) -> 218000
M45: Taycan Turbo S | N45: =SUMIF(Dados_Tratados!$D$5:$D$104,M45,Dados_Tratados!$F$5:$F$104) -> 432000 | Q45: =INDEX($Q$6:$Q$38,MATCH(R45,$R$6:$R$38,0)) -> AZ | R45: =LARGE($R$6:$R$38,3) -> 695950 | Y45: Lisa Ray | Z45: =SUMIF(Dados_Tratados!$K$5:$K$104,Y45,Dados_Tratados!$F$5:$F$104) -> 104500
Q46: =INDEX($Q$6:$Q$38,MATCH(R46,$R$6:$R$38,0)) -> NV | R46: =LARGE($R$6:$R$38,4) -> 643400 | Y46: Maria Foster | Z46: =SUMIF(Dados_Tratados!$K$5:$K$104,Y46,Dados_Tratados!$F$5:$F$104) -> 119900
Q47: =INDEX($Q$6:$Q$38,MATCH(R47,$R$6:$R$38,0)) -> FL | R47: =LARGE($R$6:$R$38,5) -> 566600 | Y47: Maria Green | Z47: =SUMIF(Dados_Tratados!$K$5:$K$104,Y47,Dados_Tratados!$F$5:$F$104) -> 66750
M48: Top 10 Modelos por Faturamento | Q48: =INDEX($Q$6:$Q$38,MATCH(R48,$R$6:$R$38,0)) -> OH | R48: =LARGE($R$6:$R$38,6) -> 523850 | Y48: Mark Evans | Z48: =SUMIF(Dados_Tratados!$K$5:$K$104,Y48,Dados_Tratados!$F$5:$F$104) -> 96300
M49: Modelo | N49: Faturamento (R$) | Q49: =INDEX($Q$6:$Q$38,MATCH(R49,$R$6:$R$38,0)) -> NC | R49: =LARGE($R$6:$R$38,7) -> 510100 | Y49: Martin Brooks | Z49: =SUMIF(Dados_Tratados!$K$5:$K$104,Y49,Dados_Tratados!$F$5:$F$104) -> 209000
M50: =INDEX($M$6:$M$45,MATCH(N50,$N$6:$N$45,0)) -> 911 Dakar | N50: =LARGE($N$6:$N$45,1) -> 810600 | Q50: =INDEX($Q$6:$Q$38,MATCH(R50,$R$6:$R$38,0)) -> GA | R50: =LARGE($R$6:$R$38,8) -> 434800 | Y50: Martin Young | Z50: =SUMIF(Dados_Tratados!$K$5:$K$104,Y50,Dados_Tratados!$F$5:$F$104) -> 198400
M51: =INDEX($M$6:$M$45,MATCH(N51,$N$6:$N$45,0)) -> 911 Turbo S | N51: =LARGE($N$6:$N$45,2) -> 726300 | Q51: =INDEX($Q$6:$Q$38,MATCH(R51,$R$6:$R$38,0)) -> LA | R51: =LARGE($R$6:$R$38,9) -> 361400 | Y51: Megan Reed | Z51: =SUMIF(Dados_Tratados!$K$5:$K$104,Y51,Dados_Tratados!$F$5:$F$104) -> 307000
...

Sheet Dashboard
A1: 🏎️ Dashboard de Vendas — Porsche
A2: Painel de indicadores comerciais gerado a partir da base tratada pelo Agente de Tratamento de Dados (ver abas Dados_Tratados e Qualidade_Dados)
A4: FATURAMENTO TOTAL | D4: VEÍCULOS VENDIDOS | G4: TICKET MÉDIO | J4: KM MÉDIA RODADA
A5: =SUM(Dados_Tratados!$F$5:$F$104) -> 12827800 | D5: =COUNTA(Dados_Tratados!$A$5:$A$104) -> 100 | G5: =SUM(Dados_Tratados!$F$5:$F$104)/COUNTA(Dados_Tratados!$A$5:$A$104) -> 128278.01 | J5: =AVERAGE(Dados_Tratados!$G$5:$G$104) -> 11422.1
A7: MODELO MAIS VENDIDO (R$) | E7: ESTADO LÍDER (UF) | H7: DATAS VÁLIDAS
A8: =Resumo!M50 -> 911 Dakar | E8: =Resumo!Q43 -> TX | H8: =TEXT((COUNTA(Dados_Tratados!$A$5:$A$104)-COUNTIF(Dados_Tratados!$B$5:$B$104,"Data inválida"))/COUNTA(Dados_Tratados!$A$5:$A$104),"0.0%") & " (" & COUNTIF(Dados_Tratados!$B$5:$B$104,"Data inválida") & " p/ revisar)" -> 76.0% (24 p/ revisar)
A65: Todos os indicadores e gráficos são calculados a partir da aba "Dados_Tratados" (saída do Agente de Tratamento de Dados), agregada na aba "Resumo". Os KPIs de faturamento consideram TODAS as vendas, mesmo as com data inválida; os gráficos que dependem de data/ano excluem essas vendas — ver aba Qualidade_Dados para o detalhamento. Para atualizar, gere uma nova base tratada executando agente_tratamento_dados.py sobre uma base bruta atualizada.
